import os
import subprocess
import sys
import unittest

from deflake import Deflake


class DeflakeTestCase(unittest.TestCase):
    THIS_DIR = os.path.dirname(os.path.realpath(__file__))

    def _results_are_same_and_pass(self, results):
        return all(results[0] == result and result == "PASS" for result in results)

    def test_default_no_fail(self):
        flake = Deflake("ls", quiet=True)
        results = flake.run()
        self.assertEqual(len(results), 10,
            "Program should have run 10 times but ran %s" % len(results))
        self.assertTrue(self._results_are_same_and_pass(results))

    def test_max_runs_no_fail(self):
        flake = Deflake("ls", max_runs=21, quiet=True)
        results = flake.run()
        self.assertEqual(len(results), 21, 
            "Program should have run 21 times but ran %s" % len(results))
        self.assertTrue(self._results_are_same_and_pass(results))

    @unittest.skipIf("3.4" in sys.version, "poolsize generates too many processes for Python 3.4")
    def test_mp(self):
        flake = Deflake("ls", pool_size=4, quiet=True)
        results = flake.run()
        len_results = len(results)
        self.assertEqual(len_results, 10, 
            "Program should have run 10 times, but ran %s" % len_results)
        self.assertTrue(self._results_are_same_and_pass(results))

    def test_passing_exist_code(self):
        code = subprocess.check_call("deflake -q 'exit 0'", shell=True)
        self.assertEquals(code, 0)

    def test_failing_exit_code(self):
        code = 0
        try:
            code = subprocess.check_call("deflake -q 'exit 1'", shell=True)
            self.fail("Deflaking a failing process should raise a subprocess.CalledProcessError")
        except subprocess.CalledProcessError:
            pass

    def test_continue_exit_code(self):
        try:
            subprocess.check_call(
                "deflake -q --continue %s" % os.path.join(self.THIS_DIR, "flaky.sh"),
                shell=True
            )
            self.fail(
                "Even when continuing through a failure, deflaking a failing process should raise a subprocess.CalledProcessError"
            )
        except subprocess.CalledProcessError:
            pass

    def test_fail(self):
        flake = Deflake(os.path.join(self.THIS_DIR, "flaky.sh"), quiet=True)
        results = flake.run()
        self.assertEqual(len(results), 7)
        self.assertEqual(results[-1], "FAIL (run 7)\nforced error\n")

    def test_continue(self):
        flake = Deflake(os.path.join(self.THIS_DIR, "flaky.sh"), quiet=True, contin=True)
        results = flake.run()
        self.assertEqual(len(results), 10)
        self.assertTrue("FAIL (run 7" in results[6])

    def test_counter_token(self):
        flake = Deflake("touch file#count#.txt", max_runs=2, quiet=True)
        results = flake.run()
        self.assertTrue(os.path.exists('file1.txt') and os.path.exists('file2.txt'))

    def setUp(self):
        self._reset_counter()

    def _reset_counter(self):
        counter = open(os.path.join(self.THIS_DIR, ".counter"), "w")
        counter.write("0")
        counter.close()

    def tearDown(self):
        try:
            os.remove(os.path.join(self.THIS_DIR, 'file1.txt'))
            os.remove(os.path.join(self.THIS_DIR, 'file2.txt'))
        except OSError:
            pass
